<robot name="leap_right">
  <!-- add xyz, rpy joints -->
  <link name="base_link_x"/>

  <joint name="dummy_x_translation_joint" type="prismatic">
    <parent link="base_link_x"/>
    <child link="base_link_y"/>
    <origin rpy="0 0 0" xyz="0 0 0"/>
    <axis xyz="1 0 0"/>
    <limit effort="300" lower="-10" upper="10" velocity="2.1750"/>
  </joint>

  <link name="base_link_y"/>

  <joint name="dummy_y_translation_joint" type="prismatic">
    <parent link="base_link_y"/>
    <child link="base_link_z"/>
    <origin rpy="0 0 0" xyz="0 0 0"/>
    <axis xyz="0 1 0"/>
    <limit effort="300" lower="-10" upper="10" velocity="2.1750"/>
  </joint>

  <link name="base_link_z"/>

  <joint name="dummy_z_translation_joint" type="prismatic">
    <parent link="base_link_z"/>
    <child link="base_link_roll"/>
    <origin rpy="0 0 0" xyz="0 0 0"/>
    <axis xyz="0 0 1"/>
    <limit effort="300" lower="-10" upper="10" velocity="2.1750"/>
  </joint>

  <link name="base_link_roll"/>

  <joint name="dummy_x_rotation_joint" type="revolute">
    <parent link="base_link_roll"/>
    <child link="base_link_pitch"/>
    <origin rpy="0 0 0" xyz="0 0 0"/>
    <axis xyz="1 0 0"/>
    <limit effort="100.95" velocity="108.48" lower="-100.283185" upper="100.283185"/>
  </joint>

  <link name="base_link_pitch"/>

  <joint name="dummy_y_rotation_joint" type="revolute">
    <parent link="base_link_pitch"/>
    <child link="base_link_yaw"/>
    <origin rpy="0 0 0" xyz="0 0 0"/>
    <axis xyz="0 1 0"/>
    <limit effort="100.95" velocity="108.48" lower="-100.283185" upper="100.283185"/>
  </joint>

  <link name="base_link_yaw"/>

  <joint name="dummy_z_rotation_joint" type="revolute">
    <parent link="base_link_yaw"/>
    <child link="base"/>
    <origin rpy="0 0 0" xyz="0 0 0"/>
    <axis xyz="0 0 1"/>
    <limit effort="100.95" velocity="108.48" lower="-100.283185" upper="100.283185"/>
  </joint>

  <link name="base"/>

  <joint name="base_joint" type="fixed">
    <parent link="base"/>
    <child link="palm_lower"/>
    <origin xyz="0 0.038 0.098" rpy="0 -1.57079 0"/>
  </joint>

  <link name="palm_lower">
    <inertial>
      <origin xyz="0 0 0" rpy="0 0 0"/>
      <mass value="0.237"/>
      <inertia ixx="0.000354094" ixy="-0.000001193" ixz="-0.000002445" iyy="0.000260915" iyz="-0.000002905" izz="0.000529257"/>
    </inertial>
  </link>

  <!-- palm balls -->

  <link name="palm_lower_collision_ball_0">
    <visual>
    <geometry>
    <sphere radius="0.025"/>
    </geometry>
    <material name="purple">
    <color rgba="1.0 0.0 1.0 1.0"/>
    </material>
    </visual>
    <collision>
    <geometry>
    <sphere radius="0.025"/>
    </geometry>
    </collision>
  </link>
  <joint name="palm_lower_collision_ball_0_joint" type="fixed">
    <parent link="palm_lower"/>
    <child link="palm_lower_collision_ball_0"/>
    <origin rpy="0 0 0" xyz="-0.045 0.005 -0.012 "/>
  </joint>

  <link name="palm_lower_collision_ball_1">
    <visual>
    <geometry>
    <sphere radius="0.025"/>
    </geometry>
    <material name="purple">
    <color rgba="1.0 0.0 1.0 1.0"/>
    </material>
    </visual>
    <collision>
    <geometry>
    <sphere radius="0.025"/>
    </geometry>
    </collision>
  </link>
  <joint name="palm_lower_collision_ball_1_joint" type="fixed">
    <parent link="palm_lower"/>
    <child link="palm_lower_collision_ball_1"/>
    <origin rpy="0 0 0" xyz="-0.045 -0.035 -0.012 "/>
  </joint>

  <link name="palm_lower_collision_ball_2">
    <visual>
    <geometry>
    <sphere radius="0.025"/>
    </geometry>
    <material name="purple">
    <color rgba="1.0 0.0 1.0 1.0"/>
    </material>
    </visual>
    <collision>
    <geometry>
    <sphere radius="0.025"/>
    </geometry>
    </collision>
  </link>
  <joint name="palm_lower_collision_ball_2_joint" type="fixed">
    <parent link="palm_lower"/>
    <child link="palm_lower_collision_ball_2"/>
    <origin rpy="0 0 0" xyz="-0.045 -0.075 -0.012 "/>
  </joint>

  <link name="palm_lower_collision_ball_3">
    <visual>
    <geometry>
    <sphere radius="0.025"/>
    </geometry>
    <material name="purple">
    <color rgba="1.0 0.0 1.0 1.0"/>
    </material>
    </visual>
    <collision>
    <geometry>
    <sphere radius="0.025"/>
    </geometry>
    </collision>
  </link>
  <joint name="palm_lower_collision_ball_3_joint" type="fixed">
    <parent link="palm_lower"/>
    <child link="palm_lower_collision_ball_3"/>
    <origin rpy="0 0 0" xyz="-0.075 -0.065 -0.012 "/>
  </joint>

  <link name="palm_lower_collision_ball_4">
    <visual>
    <geometry>
    <sphere radius="0.025"/>
    </geometry>
    <material name="purple">
    <color rgba="1.0 0.0 1.0 1.0"/>
    </material>
    </visual>
    <collision>
    <geometry>
    <sphere radius="0.025"/>
    </geometry>
    </collision>
  </link>
  <joint name="palm_lower_collision_ball_4_joint" type="fixed">
    <parent link="palm_lower"/>
    <child link="palm_lower_collision_ball_4"/>
    <origin rpy="0 0 0" xyz="-0.075 -0.035 -0.012 "/>
  </joint>

  <link name="palm_lower_collision_ball_5">
    <visual>
    <geometry>
    <sphere radius="0.019"/>
    </geometry>
    <material name="purple">
    <color rgba="1.0 0.0 1.0 1.0"/>
    </material>
    </visual>
    <collision>
    <geometry>
    <sphere radius="0.019"/>
    </geometry>
    </collision>
  </link>
  <joint name="palm_lower_collision_ball_5_joint" type="fixed">
    <parent link="palm_lower"/>
    <child link="palm_lower_collision_ball_5"/>
    <origin rpy="0 0 0" xyz="-0.012 0.008 -0.011 "/>
  </joint>

  <link name="palm_lower_collision_ball_6">
    <visual>
    <geometry>
    <sphere radius="0.019"/>
    </geometry>
    <material name="purple">
    <color rgba="1.0 0.0 1.0 1.0"/>
    </material>
    </visual>
    <collision>
    <geometry>
    <sphere radius="0.019"/>
    </geometry>
    </collision>
  </link>
  <joint name="palm_lower_collision_ball_6_joint" type="fixed">
    <parent link="palm_lower"/>
    <child link="palm_lower_collision_ball_6"/>
    <origin rpy="0 0 0" xyz="-0.012 -0.037 -0.011 "/>
  </joint>

  <link name="palm_lower_collision_ball_7">
    <visual>
    <geometry>
    <sphere radius="0.019"/>
    </geometry>
    <material name="purple">
    <color rgba="1.0 0.0 1.0 1.0"/>
    </material>
    </visual>
    <collision>
    <geometry>
    <sphere radius="0.019"/>
    </geometry>
    </collision>
  </link>
  <joint name="palm_lower_collision_ball_7_joint" type="fixed">
    <parent link="palm_lower"/>
    <child link="palm_lower_collision_ball_7"/>
    <origin rpy="0 0 0" xyz="-0.012 -0.082 -0.011 "/>
  </joint>

  <!-- index default -->

  <link name="mcp_joint">
    <inertial>
      <origin xyz="0 0 0" rpy="0 0 0"/>
      <mass value="0.044"/>
      <inertia ixx="0.000011499" ixy="0.000003049" ixz="0.000000121" iyy="0.000007796" iyz="0.000000112" izz="0.000014759"/>
    </inertial>
  </link>
  <link name="pip">
    <inertial>
      <origin xyz="0 0 0" rpy="0 0 0"/>
      <mass value="0.032"/>
      <inertia ixx="0.000004798" ixy="0.000000012" ixz="0.000000004" iyy="0.000002862" iyz="0.000000011" izz="0.000004234"/>
    </inertial>
  </link>
  <link name="dip">
    <inertial>
      <origin xyz="0 0 0" rpy="0 0 0"/>
      <mass value="0.037"/>
      <inertia ixx="0.000005542" ixy="-0.000000607" ixz="-0.000000017" iyy="0.000005727" iyz="-0.000000023" izz="0.000006682"/>
    </inertial>
  </link>
  <link name="fingertip">
    <inertial>
      <origin xyz="0 0 0" rpy="0 0 0"/>
      <mass value="0.016"/>
      <inertia ixx="0.000003368" ixy="0.000000115" ixz="0" iyy="0.000001556" iyz="0" izz="0.000002863"/>
    </inertial>
  </link>

  <joint name="0" type="revolute">
    <origin xyz="-0.0122 0.03810 0.01450" rpy="-1.57079 0 1.57079"/>
    <parent link="mcp_joint"/>
    <child link="pip"/>
    <axis xyz="0 0 -1"/>
    <limit effort="0.95" velocity="8.48" lower="-1.047" upper="1.047"/>
    <joint_properties friction="0.0"/>
  </joint>
  <joint name="1" type="revolute">
    <origin xyz="-0.0070 0.0230 -0.0187" rpy="1.57079 1.57079 0"/>
    <parent link="palm_lower"/>
    <child link="mcp_joint"/>
    <axis xyz="0 0 -1"/>
    <limit effort="0.95" velocity="8.48" lower="-0.314" upper="2.23"/>
    <joint_properties friction="0.0"/>
  </joint>
  <joint name="2" type="revolute">
    <origin xyz="0.015 0.0143 -0.013" rpy="1.57079 -1.57079 0"/>
    <parent link="pip"/>
    <child link="dip"/>
    <axis xyz="0 0 -1"/>
    <limit effort="0.95" velocity="8.48" lower="-0.506" upper="1.885"/>
    <joint_properties friction="0.0"/>
  </joint>
  <joint name="3" type="revolute">
    <origin xyz="0 -0.0361 0.0002" rpy="0 0 0"/>
    <parent link="dip"/>
    <child link="fingertip"/>
    <axis xyz="0 0 -1"/>
    <limit effort="0.95" velocity="8.48" lower="-0.366" upper="2.042"/>
    <joint_properties friction="0.0"/>
  </joint>

  <!-- index balls -->

  <link name="fingertip_collision_ball_0">
    <visual>
      <geometry>
        <sphere radius="0.0134"/>
      </geometry>
      <material name="blue">
      <color rgba="0.0 0.0 1.0 1.0"/>
    </material>
    </visual>
    <collision>
      <geometry>
      <sphere radius="0.0134"/>
      </geometry>
    </collision>
  </link>
  <joint name="fingertip_collision_ball_0_joint" type="fixed">
    <parent link="fingertip"/>
    <child link="fingertip_collision_ball_0"/>
    <origin rpy="0 0 0" xyz="-0.0015 -0.0382 0.0145"/>
  </joint>

  <link name="fingertip_collision_ball_1">
    <visual>
      <geometry>
      <sphere radius="0.0134"/>
      </geometry>
      <material name="blue">
      <color rgba="0.0 0.0 1.0 1.0"/>
      </material>
    </visual>
    <collision>
      <geometry>
      <sphere radius="0.0134"/>
      </geometry>
    </collision>

  </link>
  <joint name="fingertip_collision_ball_1_joint" type="fixed">
    <parent link="fingertip"/>
    <child link="fingertip_collision_ball_1"/>
    <origin rpy="0 0 0" xyz="-0.0015 -0.0162 0.0145"/>
  </joint>

  <link name="fingertip_collision_ball_2">
    <visual>
      <geometry>
      <sphere radius="0.0134"/>
      </geometry>
      <material name="blue">
      <color rgba="0.0 0.0 1.0 1.0"/>
      </material>
    </visual>
    <collision>
      <geometry>
      <sphere radius="0.0134"/>
      </geometry>
    </collision>

  </link>
  <joint name="fingertip_collision_ball_2_joint" type="fixed">
    <parent link="fingertip"/>
    <child link="fingertip_collision_ball_2"/>
    <origin rpy="0 0 0" xyz="-0.0015 -0.0272 0.0145"/>
  </joint>

  <link name="dip_collision_ball_0">
    <visual>
      <geometry>
      <sphere radius="0.0184"/>
      </geometry>
      <material name="blue">
      <color rgba="0.0 0.0 1.0 1.0"/>
      </material>
    </visual>
    <collision>
      <geometry>
      <sphere radius="0.0184"/>
      </geometry>
    </collision>
  </link>
  <joint name="dip_collision_ball_0_joint" type="fixed">
    <parent link="dip"/>
    <child link="dip_collision_ball_0"/>
    <origin rpy="0 0 0" xyz="0.004 -0.035  0.014"/>
  </joint>

  <link name="dip_collision_ball_1">
    <visual>
    <geometry>
    <sphere radius="0.0184"/>
    </geometry>
    <material name="blue">
    <color rgba="0.0 0.0 1.0 1.0"/>
    </material>
    </visual>
    <collision>
    <geometry>
    <sphere radius="0.0184"/>
    </geometry>
    </collision>
  </link>
  <joint name="dip_collision_ball_1_joint" type="fixed">
    <parent link="dip"/>
    <child link="dip_collision_ball_1"/>
    <origin rpy="0 0 0" xyz="0.004 -0.012  0.014"/>
  </joint>

  <link name="dip_collision_ball_2">
    <visual>
      <geometry>
      <sphere radius="0.0184"/>
      </geometry>
      <material name="blue">
      <color rgba="0.0 0.0 1.0 1.0"/>
      </material>
    </visual>
    <collision>
      <geometry>
      <sphere radius="0.0184"/>
      </geometry>
    </collision>
  </link>
  <joint name="dip_collision_ball_2_joint" type="fixed">
    <parent link="dip"/>
    <child link="dip_collision_ball_2"/>
    <origin rpy="0 0 0" xyz="0.014 -0.035  0.014"/>
  </joint>

  <link name="pip_collision_ball_0">
    <visual>
    <geometry>
    <sphere radius="0.0184"/>
    </geometry>
    <material name="blue">
    <color rgba="0.0 0.0 1.0 1.0"/>
    </material>
    </visual>
    <collision>
    <geometry>
    <sphere radius="0.0184"/>
    </geometry>
    </collision>
  </link>
  <joint name="pip_collision_ball_0_joint" type="fixed">
    <parent link="pip"/>
    <child link="pip_collision_ball_0"/>
    <origin rpy="0 0 0" xyz="0.00 0.0 -0.008"/>  
  </joint>

  <link name="pip_collision_ball_1">
    <visual>
    <geometry>
    <sphere radius="0.0184"/>
    </geometry>
    <material name="blue">
    <color rgba="0.0 0.0 1.0 1.0"/>
    </material>
    </visual>
    <collision>
    <geometry>
    <sphere radius="0.0184"/>
    </geometry>
    </collision>
  </link>
  <joint name="pip_collision_ball_1_joint" type="fixed">
    <parent link="pip"/>
    <child link="pip_collision_ball_1"/>
    <origin rpy="0 0 0" xyz="0.015 -0.0025 0.02"/>  
  </joint>

  <link name="pip_collision_ball_2">
    <visual>
    <geometry>
    <sphere radius="0.0184"/>
    </geometry>
    <material name="blue">
    <color rgba="0.0 0.0 1.0 1.0"/>
    </material>
    </visual>
    <collision>
    <geometry>
    <sphere radius="0.0184"/>
    </geometry>
    </collision>
  </link>
  <joint name="pip_collision_ball_2_joint" type="fixed">
    <parent link="pip"/>
    <child link="pip_collision_ball_2"/>
    <origin rpy="0 0 0" xyz="-0.01 -0.0025 0.02"/>  
  </joint>

  <link name="mcp_joint_collision_ball_0">
    <visual>
      <geometry>
      <sphere radius="0.0184"/>
      </geometry>
      <material name="blue">
      <color rgba="0.0 0.0 1.0 1.0"/>
      </material>
    </visual>
    <collision>
      <geometry>
      <sphere radius="0.0184"/>
      </geometry>
    </collision>
  </link>
  <joint name="mcp_joint_collision_ball_0_joint" type="fixed">
    <parent link="mcp_joint"/>
    <child link="mcp_joint_collision_ball_0"/>
    <origin rpy="0 0 0" xyz="-0.005 0.01 0.015"/>
  </joint>

  <!-- middle default -->

  <link name="mcp_joint_2">
    <inertial>
    <origin xyz="0 0 0" rpy="0 0 0"/>
    <mass value="0.044" />
    <inertia ixx="0.000011499" ixy="0.000003049"  ixz="0.000000121" iyy="0.000007796" iyz="0.000000112" izz="0.000014759" />
    </inertial>
  </link>
  <link name="pip_2">
    <inertial>
    <origin xyz="0 0 0" rpy="0 0 0"/>
    <mass value="0.032" />
    <inertia ixx="0.000004798" ixy="0.000000012"  ixz="0.000000004" iyy="0.000002862" iyz="0.000000011" izz="0.000004234" />
    </inertial>
  </link>
  <link name="dip_2">
    <inertial>
    <origin xyz="0 0 0" rpy="0 0 0"/>
    <mass value="0.037" />
    <inertia ixx="0.000005542" ixy="-0.000000607"  ixz="-0.000000017" iyy="0.000005727" iyz="-0.000000023" izz="0.000006682" />
    </inertial>
  </link>
  <link name="fingertip_2">
    <inertial>
    <origin xyz="0 0 0" rpy="0 0 0"/>
    <mass value="0.016" />
    <inertia ixx="0.000003368" ixy="0.000000115"  ixz="0" iyy="0.000001556" iyz="0" izz="0.000002863" />
    </inertial>
  </link>

  <joint name="4" type="revolute">
    <origin xyz="-0.0122 0.0381 0.0145" rpy="-1.57079 0 1.57079"/>
    <parent link="mcp_joint_2"/>
    <child link="pip_2"/>
    <axis xyz="0 0 -1"/>
    <limit effort="0.95" velocity="8.48" lower="-1.047" upper="1.047"/>
    <joint_properties friction="0.0"/>
  </joint>
  <joint name="5" type="revolute">
    <origin xyz="-0.0071 -0.0224 -0.0187" rpy="1.57079 1.57079 0"/>
    <parent link="palm_lower"/>
    <child link="mcp_joint_2"/>
    <axis xyz="0 0 -1"/>
    <limit effort="0.95" velocity="8.48" lower="-0.314" upper="2.23"/>
    <joint_properties friction="0.0"/>
  </joint>
  <joint name="6" type="revolute">
    <origin xyz="0.015 0.0143 -0.013" rpy="1.57079 -1.57079 0"/>
    <parent link="pip_2"/>
    <child link="dip_2"/>
    <axis xyz="0 0 -1"/>
    <limit effort="0.95" velocity="8.48" lower="-0.506" upper="1.885"/>
    <joint_properties friction="0.0"/>
  </joint>
  <joint name="7" type="revolute">
    <origin xyz="0 -0.0361 0.0002" rpy="0 0 0"/>
    <parent link="dip_2"/>
    <child link="fingertip_2"/>
    <axis xyz="0 0 -1"/>
    <limit effort="0.95" velocity="8.48" lower="-0.366" upper="2.042"/>
    <joint_properties friction="0.0"/>
  </joint>

  <!-- middle balls -->

  <link name="fingertip_2_collision_ball_0">
    <visual>
    <geometry>
    <sphere radius="0.0134"/>
    </geometry>
    <material name="blue">
    <color rgba="0.0 0.0 1.0 1.0"/>
    </material>
    </visual>
    <collision>
    <geometry>
    <sphere radius="0.0134"/>
    </geometry>
    </collision>
  </link>
  <joint name="fingertip_2_collision_ball_0_joint" type="fixed">
    <parent link="fingertip_2"/>
    <child link="fingertip_2_collision_ball_0"/>
    <origin rpy="0 0 0" xyz="-0.0015 -0.0382 0.0145"/>
  </joint>

  <link name="fingertip_2_collision_ball_1">
    <visual>
    <geometry>
    <sphere radius="0.0134"/>
    </geometry>
    <material name="blue">
    <color rgba="0.0 0.0 1.0 1.0"/>
    </material>
    </visual>
    <collision>
    <geometry>
    <sphere radius="0.0134"/>
    </geometry>
    </collision>
  </link>
  <joint name="fingertip_2_collision_ball_1_joint" type="fixed">
    <parent link="fingertip_2"/>
    <child link="fingertip_2_collision_ball_1"/>
    <origin rpy="0 0 0" xyz="-0.0015 -0.0162 0.0145"/>
  </joint>

  <link name="fingertip_2_collision_ball_2">
    <visual>
      <geometry>
      <sphere radius="0.0134"/>
      </geometry>
      <material name="blue">
      <color rgba="0.0 0.0 1.0 1.0"/>
      </material>
    </visual>
    <collision>
      <geometry>
      <sphere radius="0.0134"/>
      </geometry>
    </collision>
  </link>
  <joint name="fingertip_2_collision_ball_2_joint" type="fixed">
    <parent link="fingertip_2"/>
    <child link="fingertip_2_collision_ball_2"/>
    <origin rpy="0 0 0" xyz="-0.0015 -0.0272 0.0145"/>
  </joint>

  <link name="dip_2_collision_ball_0">
    <visual>
      <geometry>
      <sphere radius="0.0184"/>
      </geometry>
      <material name="blue">
      <color rgba="0.0 0.0 1.0 1.0"/>
      </material>
    </visual>
    <collision>
      <geometry>
      <sphere radius="0.0184"/>
      </geometry>
    </collision>
  </link>
  <joint name="dip_2_collision_ball_0_joint" type="fixed">
    <parent link="dip_2"/>
    <child link="dip_2_collision_ball_0"/>
    <origin rpy="0 0 0" xyz="0.004 -0.035  0.014"/>
  </joint>

  <link name="dip_2_collision_ball_1">
    <visual>
    <geometry>
    <sphere radius="0.0184"/>
    </geometry>
    <material name="blue">
    <color rgba="0.0 0.0 1.0 1.0"/>
    </material>
    </visual>
    <collision>
    <geometry>
    <sphere radius="0.0184"/>
    </geometry>
    </collision>
  </link>
  <joint name="dip_2_collision_ball_1_joint" type="fixed">
    <parent link="dip_2"/>
    <child link="dip_2_collision_ball_1"/>
    <origin rpy="0 0 0" xyz="0.004 -0.012  0.014"/>
  </joint>

  <link name="dip_2_collision_ball_2">
    <visual>
      <geometry>
      <sphere radius="0.0184"/>
      </geometry>
      <material name="blue">
      <color rgba="0.0 0.0 1.0 1.0"/>
      </material>
    </visual>
    <collision>
      <geometry>
      <sphere radius="0.0184"/>
      </geometry>
    </collision>
  </link>
  <joint name="dip_2_collision_ball_2_joint" type="fixed">
    <parent link="dip_2"/>
    <child link="dip_2_collision_ball_2"/>
    <origin rpy="0 0 0" xyz="0.014 -0.035  0.014"/>
  </joint>

  <link name="pip_2_collision_ball_0">
    <visual>
    <geometry>
    <sphere radius="0.0184"/>
    </geometry>
    <material name="blue">
    <color rgba="0.0 0.0 1.0 1.0"/>
    </material>
    </visual>
    <collision>
    <geometry>
    <sphere radius="0.0184"/>
    </geometry>
    </collision>
  </link>
  <joint name="pip_2_collision_ball_0_joint" type="fixed">
    <parent link="pip_2"/>
    <child link="pip_2_collision_ball_0"/>
    <origin rpy="0 0 0" xyz="0.00 0.0 -0.008"/>  
  </joint>

  <link name="pip_2_collision_ball_1">
    <visual>
    <geometry>
    <sphere radius="0.0184"/>
    </geometry>
    <material name="blue">
    <color rgba="0.0 0.0 1.0 1.0"/>
    </material>
    </visual>
    <collision>
    <geometry>
    <sphere radius="0.0184"/>
    </geometry>
    </collision>
  </link>
  <joint name="pip_2_collision_ball_1_joint" type="fixed">
    <parent link="pip_2"/>
    <child link="pip_2_collision_ball_1"/>
    <origin rpy="0 0 0" xyz="0.015 -0.0025 0.02"/> 
  </joint>

  <link name="pip_2_collision_ball_2">
    <visual>
    <geometry>
    <sphere radius="0.0184"/>
    </geometry>
    <material name="blue">
    <color rgba="0.0 0.0 1.0 1.0"/>
    </material>
    </visual>
    <collision>
    <geometry>
    <sphere radius="0.0184"/>
    </geometry>
    </collision>
  </link>
  <joint name="pip_2_collision_ball_2_joint" type="fixed">
    <parent link="pip_2"/>
    <child link="pip_2_collision_ball_2"/>
    <origin rpy="0 0 0" xyz="-0.01 -0.0025 0.02"/>  
  </joint>

  <link name="mcp_joint_2_collision_ball_0">
    <visual>
    <geometry>
    <sphere radius="0.0184"/>
    </geometry>
    <material name="blue">
    <color rgba="0.0 0.0 1.0 1.0"/>
    </material>
    </visual>
    <collision>
    <geometry>
    <sphere radius="0.0184"/>
    </geometry>
    </collision>
  </link>
  <joint name="mcp_joint_2_collision_ball_0_joint" type="fixed">
    <parent link="mcp_joint_2"/>
    <child link="mcp_joint_2_collision_ball_0"/>
    <origin rpy="0 0 0" xyz="-0.005 0.01 0.015"/>
  </joint>


  <!-- ring default -->

  <link name="mcp_joint_3">
    <inertial>
      <origin xyz="0 0 0" rpy="0 0 0"/>
      <mass value="0.044"/>
      <inertia ixx="0.000011499" ixy="0.000003049" ixz="0.000000121" iyy="0.000007796" iyz="0.000000112" izz="0.000014759"/>
    </inertial>
  </link>
  <link name="pip_3">
    <inertial>
      <origin xyz="0 0 0" rpy="0 0 0"/>
      <mass value="0.032"/>
      <inertia ixx="0.000004798" ixy="0.000000012" ixz="0.000000004" iyy="0.000002862" iyz="0.000000011" izz="0.000004234"/>
    </inertial>
  </link>
  <link name="dip_3">
    <inertial>
      <origin xyz="0 0 0" rpy="0 0 0"/>
      <mass value="0.037"/>
      <inertia ixx="0.000005542" ixy="-0.000000607" ixz="-0.000000017" iyy="0.000005727" iyz="-0.000000023" izz="0.000006682"/>
    </inertial>
  </link>
  <link name="fingertip_3">
    <inertial>
      <origin xyz="0 0 0" rpy="0 0 0"/>
      <mass value="0.016"/>
      <inertia ixx="0.000003368" ixy="0.000000115" ixz="0" iyy="0.000001556" iyz="0" izz="0.000002863"/>
    </inertial>
  </link>
  <joint name="8" type="revolute">
    <origin xyz="-0.0122 0.0381 0.0145" rpy="-1.57079 0 1.57079"/>
    <parent link="mcp_joint_3"/>
    <child link="pip_3"/>
    <axis xyz="0 0 -1"/>
    <limit effort="0.95" velocity="8.48" lower="-1.047" upper="1.047"/>
    <joint_properties friction="0.0"/>
  </joint>
  <joint name="9" type="revolute">
    <origin xyz="-0.00709 -0.0678 -0.0187" rpy="1.57079 1.57079 0"/>
    <parent link="palm_lower"/>
    <child link="mcp_joint_3"/>
    <axis xyz="0 0 -1"/>
    <limit effort="0.95" velocity="8.48" lower="-0.314" upper="2.23"/>
    <joint_properties friction="0.0"/>
  </joint>
  <joint name="10" type="revolute">
    <origin xyz="0.015 0.0143 -0.013" rpy="1.57079 -1.57079 0"/>
    <parent link="pip_3"/>
    <child link="dip_3"/>
    <axis xyz="0 0 -1"/>
    <limit effort="0.95" velocity="8.48" lower="-0.506" upper="1.885"/>
    <joint_properties friction="0.0"/>
  </joint>
  <joint name="11" type="revolute">
    <origin xyz="0 -0.03609 0.0002" rpy="0 0 0"/>
    <parent link="dip_3"/>
    <child link="fingertip_3"/>
    <axis xyz="0 0 -1"/>
    <limit effort="0.95" velocity="8.48" lower="-0.366" upper="2.042"/>
    <joint_properties friction="0.0"/>
  </joint>

  <!-- ring balls -->

  <link name="fingertip_3_collision_ball_0">
    <visual>
    <geometry>
    <sphere radius="0.0134"/>
    </geometry>
    <material name="blue">
    <color rgba="0.0 0.0 1.0 1.0"/>
    </material>
    </visual>
    <collision>
    <geometry>
    <sphere radius="0.0134"/>
    </geometry>
    </collision>
  </link>
  <joint name="fingertip_3_collision_ball_0_joint" type="fixed">
    <parent link="fingertip_3"/>
    <child link="fingertip_3_collision_ball_0"/>
    <origin rpy="0 0 0" xyz="-0.0015 -0.0382 0.0145"/>
  </joint>

  <link name="fingertip_3_collision_ball_1">
    <visual>
    <geometry>
    <sphere radius="0.0134"/>
    </geometry>
    <material name="blue">
    <color rgba="0.0 0.0 1.0 1.0"/>
    </material>
    </visual>
    <collision>
    <geometry>
    <sphere radius="0.0134"/>
    </geometry>
    </collision>
  </link>
  <joint name="fingertip_3_collision_ball_1_joint" type="fixed">
    <parent link="fingertip_3"/>
    <child link="fingertip_3_collision_ball_1"/>
    <origin rpy="0 0 0" xyz="-0.0015 -0.0162 0.0145"/>
  </joint>

  <link name="fingertip_3_collision_ball_2">
    <visual>
      <geometry>
      <sphere radius="0.0134"/>
      </geometry>
      <material name="blue">
      <color rgba="0.0 0.0 1.0 1.0"/>
      </material>
    </visual>
    <collision>
      <geometry>
      <sphere radius="0.0134"/>
      </geometry>
    </collision>
  </link>
  <joint name="fingertip_3_collision_ball_2_joint" type="fixed">
    <parent link="fingertip_3"/>
    <child link="fingertip_3_collision_ball_2"/>
    <origin rpy="0 0 0" xyz="-0.0015 -0.0272 0.0145"/>
  </joint>

  <link name="dip_3_collision_ball_0">
    <visual>
      <geometry>
      <sphere radius="0.0184"/>
      </geometry>
      <material name="blue">
      <color rgba="0.0 0.0 1.0 1.0"/>
      </material>
    </visual>
    <collision>
      <geometry>
      <sphere radius="0.0184"/>
      </geometry>
    </collision>
  </link>
  <joint name="dip_3_collision_ball_0_joint" type="fixed">
    <parent link="dip_3"/>
    <child link="dip_3_collision_ball_0"/>
    <origin rpy="0 0 0" xyz="0.004 -0.035  0.014"/>
  </joint>

  <link name="dip_3_collision_ball_1">
    <visual>
    <geometry>
    <sphere radius="0.0184"/>
    </geometry>
    <material name="blue">
    <color rgba="0.0 0.0 1.0 1.0"/>
    </material>
    </visual>
    <collision>
    <geometry>
    <sphere radius="0.0184"/>
    </geometry>
    </collision>
  </link>
  <joint name="dip_3_collision_ball_1_joint" type="fixed">
    <parent link="dip_3"/>
    <child link="dip_3_collision_ball_1"/>
    <origin rpy="0 0 0" xyz="0.004 -0.012  0.014"/>
  </joint>

  <link name="dip_3_collision_ball_2">
    <visual>
      <geometry>
      <sphere radius="0.0184"/>
      </geometry>
      <material name="blue">
      <color rgba="0.0 0.0 1.0 1.0"/>
      </material>
    </visual>
    <collision>
      <geometry>
      <sphere radius="0.0184"/>
      </geometry>
    </collision>
  </link>
  <joint name="dip_3_collision_ball_2_joint" type="fixed">
    <parent link="dip_3"/>
    <child link="dip_3_collision_ball_2"/>
    <origin rpy="0 0 0" xyz="0.014 -0.035  0.014"/>
  </joint>

  <link name="pip_3_collision_ball_0">
    <visual>
    <geometry>
    <sphere radius="0.0184"/>
    </geometry>
    <material name="blue">
    <color rgba="0.0 0.0 1.0 1.0"/>
    </material>
    </visual>
    <collision>
    <geometry>
    <sphere radius="0.0184"/>
    </geometry>
    </collision>
  </link>
  <joint name="pip_3_collision_ball_0_joint" type="fixed">
    <parent link="pip_3"/>
    <child link="pip_3_collision_ball_0"/>
    <origin rpy="0 0 0" xyz="0.00 0.0 -0.008"/>  
  </joint>

  <link name="pip_3_collision_ball_1">
    <visual>
    <geometry>
    <sphere radius="0.0184"/>
    </geometry>
    <material name="blue">
    <color rgba="0.0 0.0 1.0 1.0"/>
    </material>
    </visual>
    <collision>
    <geometry>
    <sphere radius="0.0184"/>
    </geometry>
    </collision>
  </link>
  <joint name="pip_3_collision_ball_1_joint" type="fixed">
    <parent link="pip_3"/>
    <child link="pip_3_collision_ball_1"/>
    <origin rpy="0 0 0" xyz="0.015 -0.0025 0.02"/> 
  </joint>

  <link name="pip_3_collision_ball_2">
    <visual>
    <geometry>
    <sphere radius="0.0184"/>
    </geometry>
    <material name="blue">
    <color rgba="0.0 0.0 1.0 1.0"/>
    </material>
    </visual>
    <collision>
    <geometry>
    <sphere radius="0.0184"/>
    </geometry>
    </collision>
  </link>
  <joint name="pip_3_collision_ball_2_joint" type="fixed">
    <parent link="pip_3"/>
    <child link="pip_3_collision_ball_2"/>
    <origin rpy="0 0 0" xyz="-0.01 -0.0025 0.02"/>  
  </joint>

  <link name="mcp_joint_3_collision_ball_0">
    <visual>
    <geometry>
    <sphere radius="0.0184"/>
    </geometry>
    <material name="blue">
    <color rgba="0.0 0.0 1.0 1.0"/>
    </material>
    </visual>
    <collision>
    <geometry>
    <sphere radius="0.0184"/>
    </geometry>
    </collision>
  </link>
  <joint name="mcp_joint_3_collision_ball_0_joint" type="fixed">
    <parent link="mcp_joint_3"/>
    <child link="mcp_joint_3_collision_ball_0"/>
    <origin rpy="0 0 0" xyz="-0.005 0.01 0.015"/>
  </joint>

  <!-- thumb default -->

  <link name="thumb_temp_base">
    <inertial>
      <origin xyz="0 0 0" rpy="0 0 0"/>
      <mass value="0.032"/>
      <inertia ixx="0.000004798" ixy="0.000000012" ixz="0.000000004" iyy="0.000002862" iyz="0.000000011" izz="0.000004234"/>
    </inertial>
  </link>
  <link name="thumb_pip">
    <inertial>
      <origin xyz="0 0 0" rpy="0 0 0"/>
      <mass value="0.003"/>
      <inertia ixx="0.000000593" ixy="0" ixz="0" iyy="0.000000549" iyz="0" izz="0.000000224"/>
    </inertial>
  </link>
  <link name="thumb_dip">
    <inertial>
      <origin xyz="0 0 0" rpy="0 0 0"/>
      <mass value="0.038"/>
      <inertia ixx="0.000008474" ixy="0.000000241" ixz="0.000000026" iyy="0.000003841" iyz="0.000000025" izz="0.000007679"/>
    </inertial>
  </link>
  <link name="thumb_fingertip">
    <inertial>
      <origin xyz="0 0 0" rpy="0 0 0"/>
      <mass value="0.049"/>
      <inertia ixx="0.000020372" ixy="-0.000000489" ixz="-0.00000003" iyy="0.000004336" iyz="-0.000000097" izz="0.000019845"/>
    </inertial>
  </link>
  <joint name="12" type="revolute">
    <origin xyz="-0.0693 -0.0012 -0.0216" rpy="0 1.57079 0"/>
    <parent link="palm_lower"/>
    <child link="thumb_temp_base"/>
    <axis xyz="0 0 -1"/>
    <limit effort="0.95" velocity="8.48" lower="-0.349" upper="2.094"/>
    <joint_properties friction="0.0"/>
  </joint>
  <joint name="13" type="revolute">
    <origin xyz="0 0.0143 -0.013" rpy="1.57079 -1.57079 0"/>
    <parent link="thumb_temp_base"/>
    <child link="thumb_pip"/>
    <axis xyz="0 0 -1"/>
    <limit effort="0.95" velocity="8.48" lower="-0.47" upper="2.443"/>
    <joint_properties friction="0.0"/>
  </joint>
  <joint name="14" type="revolute">
    <origin xyz="0 0.0145 -0.017" rpy="-1.57079 0 0"/>
    <parent link="thumb_pip"/>
    <child link="thumb_dip"/>
    <axis xyz="0 0 -1"/>
    <limit effort="0.95" velocity="8.48" lower="-1.20" upper="1.90"/>
    <joint_properties friction="0.0"/>
  </joint>
  <joint name="15" type="revolute">
    <origin xyz="0 0.0466 0.0002" rpy="0 0 3.14159"/>
    <parent link="thumb_dip"/>
    <child link="thumb_fingertip"/>
    <axis xyz="0 0 -1"/>
    <limit effort="0.95" velocity="8.48" lower="-1.34" upper="1.88"/>
    <joint_properties friction="0.0"/>
  </joint>

  <!-- thumb balls -->

  <link name="thumb_fingertip_collision_ball_0">
    <visual>
    <geometry>
    <sphere radius="0.0134"/>
    </geometry>
    <material name="blue">
    <color rgba="0.0 0.0 1.0 1.0"/>
    </material>
    </visual>
    <collision>
    <geometry>
    <sphere radius="0.0134"/>
    </geometry>
    </collision>
  </link>
  <joint name="thumb_fingertip_collision_ball_0_joint" type="fixed">
    <parent link="thumb_fingertip"/>
    <child link="thumb_fingertip_collision_ball_0"/>
    <origin rpy="0 0 0" xyz="-0.0015 -0.051 -0.0143"/>
  </joint>

  <link name="thumb_fingertip_collision_ball_1">
    <visual>
    <geometry>
    <sphere radius="0.0134"/>
    </geometry>
    <material name="blue">
    <color rgba="0.0 0.0 1.0 1.0"/>
    </material>
    </visual>
    <collision>
    <geometry>
    <sphere radius="0.0134"/>
    </geometry>
    </collision>
  </link>
  <joint name="thumb_fingertip_collision_ball_1_joint" type="fixed">
    <parent link="thumb_fingertip"/>
    <child link="thumb_fingertip_collision_ball_1"/>
    <origin rpy="0 0 0" xyz="-0.0015 -0.031 -0.0143"/>
  </joint>

  <link name="thumb_fingertip_collision_ball_2">
    <visual>
    <geometry>
    <sphere radius="0.0134"/>
    </geometry>
    <material name="blue">
    <color rgba="0.0 0.0 1.0 1.0"/>
    </material>
    </visual>
    <collision>
    <geometry>
    <sphere radius="0.0134"/>
    </geometry>
    </collision>
  </link>
  <joint name="thumb_fingertip_collision_ball_2_joint" type="fixed">
    <parent link="thumb_fingertip"/>
    <child link="thumb_fingertip_collision_ball_2"/>
    <origin rpy="0 0 0" xyz="-0.0015 -0.011 -0.0143"/>
  </joint>

  <link name="thumb_fingertip_collision_ball_3">
    <visual>
    <geometry>
    <sphere radius="0.0134"/>
    </geometry>
    <material name="blue">
    <color rgba="0.0 0.0 1.0 1.0"/>
    </material>
    </visual>
    <collision>
    <geometry>
    <sphere radius="0.0134"/>
    </geometry>
    </collision>
  </link>
  <joint name="thumb_fingertip_collision_ball_3_joint" type="fixed">
    <parent link="thumb_fingertip"/>
    <child link="thumb_fingertip_collision_ball_3"/>
    <origin rpy="0 0 0" xyz="-0.0015 0.009 -0.0143"/>
  </joint>

  <link name="thumb_fingertip_collision_ball_4">
    <visual>
    <geometry>
    <sphere radius="0.0134"/>
    </geometry>
    <material name="blue">
    <color rgba="0.0 0.0 1.0 1.0"/>
    </material>
    </visual>
    <collision>
    <geometry>
    <sphere radius="0.0134"/>
    </geometry>
    </collision>
  </link>
  <joint name="thumb_fingertip_collision_ball_4_joint" type="fixed">
    <parent link="thumb_fingertip"/>
    <child link="thumb_fingertip_collision_ball_4"/>
    <origin rpy="0 0 0" xyz="-0.0015 -0.041 -0.0143"/>
  </joint>

  <link name="thumb_fingertip_collision_ball_5">
    <visual>
    <geometry>
    <sphere radius="0.0134"/>
    </geometry>
    <material name="blue">
    <color rgba="0.0 0.0 1.0 1.0"/>
    </material>
    </visual>
    <collision>
    <geometry>
    <sphere radius="0.0134"/>
    </geometry>
    </collision>
  </link>
  <joint name="thumb_fingertip_collision_ball_5_joint" type="fixed">
    <parent link="thumb_fingertip"/>
    <child link="thumb_fingertip_collision_ball_5"/>
    <origin rpy="0 0 0" xyz="0.008 -0.018 -0.012"/>
  </joint>

  <link name="thumb_dip_collision_ball_0">
    <visual>
    <geometry>
    <sphere radius="0.0134"/>
    </geometry>
    <material name="blue">
    <color rgba="0.0 0.0 1.0 1.0"/>
    </material>
    </visual>
    <collision>
    <geometry>
    <sphere radius="0.0134"/>
    </geometry>
    </collision>
  </link>
  <joint name="thumb_dip_collision_ball_0_joint" type="fixed">
    <parent link="thumb_dip"/>
    <child link="thumb_dip_collision_ball_0"/>
    <origin rpy="0 0 0" xyz="0.0 0.016 -0.014"/>
  </joint>

  <link name="thumb_dip_collision_ball_1">
    <visual>
    <geometry>
    <sphere radius="0.0134"/>
    </geometry>
    <material name="blue">
    <color rgba="0.0 0.0 1.0 1.0"/>
    </material>
    </visual>
    <collision>
    <geometry>
    <sphere radius="0.0134"/>
    </geometry>
    </collision>
  </link>
  <joint name="thumb_dip_collision_ball_1_joint" type="fixed">
    <parent link="thumb_dip"/>
    <child link="thumb_dip_collision_ball_1"/>
    <origin rpy="0 0 0" xyz="0.0 -0.004 -0.014"/>
  </joint>

  <link name="thumb_dip_collision_ball_2">
    <visual>
    <geometry>
    <sphere radius="0.0134"/>
    </geometry>
    <material name="blue">
    <color rgba="0.0 0.0 1.0 1.0"/>
    </material>
    </visual>
    <collision>
    <geometry>
    <sphere radius="0.0134"/>
    </geometry>
    </collision>
  </link>
  <joint name="thumb_dip_collision_ball_2_joint" type="fixed">
    <parent link="thumb_dip"/>
    <child link="thumb_dip_collision_ball_2"/>
    <origin rpy="0 0 0" xyz="-0.008 0.018 -0.014"/>
  </joint>

  <link name="thumb_temp_base_collision_ball_0">
    <visual>
    <geometry>
    <sphere radius="0.0134"/>
    </geometry>
    <material name="blue">
    <color rgba="0.0 0.0 1.0 1.0"/>
    </material>
    </visual>
    <collision>
    <geometry>
    <sphere radius="0.0134"/>
    </geometry>
    </collision>
  </link>
  <joint name="thumb_temp_base_collision_ball_0_joint" type="fixed">
    <parent link="thumb_temp_base"/>
    <child link="thumb_temp_base_collision_ball_0"/>
    <origin rpy="0 0 0" xyz="0.0 0.01 -0.012 "/>
  </joint>

  <link name="thumb_temp_base_collision_ball_1">
    <visual>
    <geometry>
    <sphere radius="0.0134"/>
    </geometry>
    <material name="blue">
    <color rgba="0.0 0.0 1.0 1.0"/>
    </material>
    </visual>
    <collision>
    <geometry>
    <sphere radius="0.0134"/>
    </geometry>
    </collision>
  </link>
  <joint name="thumb_temp_base_collision_ball_1_joint" type="fixed">
    <parent link="thumb_temp_base"/>
    <child link="thumb_temp_base_collision_ball_1"/>
    <origin rpy="0 0 0" xyz="0.0 -0.01 -0.012 "/>
  </joint>

  <!--  virtual auxiliary link-->
  <link name="thumb_tip_head"/>
  <link name="index_tip_head"/>
  <link name="middle_tip_head"/>
  <link name="ring_tip_head"/>
  <joint name="thumb_tip" type="fixed">
    <parent link="thumb_fingertip"/>
    <child link="thumb_tip_head"/>
    <origin rpy="0 0 0" xyz="0 -0.06 -0.015"/>
  </joint>
  <joint name="index_tip" type="fixed">
    <parent link="fingertip"/>
    <child link="index_tip_head"/>
    <origin rpy="0 0 0" xyz="0 -0.048 0.015"/>
  </joint>
  <joint name="middle_tip" type="fixed">
    <parent link="fingertip_2"/>
    <child link="middle_tip_head"/>
    <origin rpy="0 0 0" xyz="0 -0.048 0.015"/>
  </joint>
  <joint name="ring_tip" type="fixed">
    <parent link="fingertip_3"/>
    <child link="ring_tip_head"/>
    <origin rpy="0 0 0" xyz="0 -0.048 0.015"/>
  </joint>
</robot>
